Workbook

Sheet Dashboard
B2: DPDPA Compliance Dashboard
B3: Kavach Financial Technologies Private Limited · assessed 2026-08-14 · all figures recalculate from the Control Matrix
B5: OVERALL MATURITY
B6: Weighted maturity score | C6: =G33 | I6: Weighted by domain, so a domain with many controls does not mechanically dominate one with few but weighty ones.
B7: Maturity band | C7: =IF(C6="","Not assessed",IF(C6>=0.8,"Optimised",IF(C6>=0.6,"Managed",IF(C6>=0.4,"Developing",IF(C6>=0.2,"Initial","Absent")))))
B8: Assessment coverage | C8: =IF(D33=0,"",E33/D33)
B9: Controls in scope / assessed | C9: =D33&" / "&E33
B10: Total gaps identified | C10: =F33
B11: Critical-severity gaps | C11: =COUNTIFS('Control Matrix'!$R$2:$R$91,1,'Control Matrix'!$E$2:$E$91,"Critical")
B14: MATURITY BY DOMAIN
B15: Domain | C15: Weight | D15: In scope | E15: Assessed | F15: Gaps | G15: Maturity | H15: Wtd num. | I15: Wtd den. | J15: Band
B16: APP — Applicability & Role Determination | C16: 1 | D16: =COUNTIFS('Control Matrix'!$B$2:$B$91,"APP",'Control Matrix'!$H$2:$H$91,"Yes") | E16: =COUNTIFS('Control Matrix'!$B$2:$B$91,"APP",'Control Matrix'!$N$2:$N$91,1) | F16: =COUNTIFS('Control Matrix'!$B$2:$B$91,"APP",'Control Matrix'!$R$2:$R$91,1) | G16: =IF(SUMIFS('Control Matrix'!$T$2:$T$91,'Control Matrix'!$B$2:$B$91,"APP")=0,"",SUMIFS('Control Matrix'!$S$2:$S$91,'Control Matrix'!$B$2:$B$91,"APP")/SUMIFS('Control Matrix'!$T$2:$T$91,'Control Matrix'!$B$2:$B$91,"APP")) | H16: =IF(G16="","",G16*C16) | I16: =IF(G16="","",C16) | J16: =IF(G16="","Not assessed",IF(G16>=0.8,"Optimised",IF(G16>=0.6,"Managed",IF(G16>=0.4,"Developing",IF(G16>=0.2,"Initial","Absent")))))
B17: GOV — Governance, Accountability & Records | C17: 1.2 | D17: =COUNTIFS('Control Matrix'!$B$2:$B$91,"GOV",'Control Matrix'!$H$2:$H$91,"Yes") | E17: =COUNTIFS('Control Matrix'!$B$2:$B$91,"GOV",'Control Matrix'!$N$2:$N$91,1) | F17: =COUNTIFS('Control Matrix'!$B$2:$B$91,"GOV",'Control Matrix'!$R$2:$R$91,1) | G17: =IF(SUMIFS('Control Matrix'!$T$2:$T$91,'Control Matrix'!$B$2:$B$91,"GOV")=0,"",SUMIFS('Control Matrix'!$S$2:$S$91,'Control Matrix'!$B$2:$B$91,"GOV")/SUMIFS('Control Matrix'!$T$2:$T$91,'Control Matrix'!$B$2:$B$91,"GOV")) | H17: =IF(G17="","",G17*C17) | I17: =IF(G17="","",C17) | J17: =IF(G17="","Not assessed",IF(G17>=0.8,"Optimised",IF(G17>=0.6,"Managed",IF(G17>=0.4,"Developing",IF(G17>=0.2,"Initial","Absent")))))
B18: PUR — Lawful Purpose, Minimisation & Accuracy | C18: 1 | D18: =COUNTIFS('Control Matrix'!$B$2:$B$91,"PUR",'Control Matrix'!$H$2:$H$91,"Yes") | E18: =COUNTIFS('Control Matrix'!$B$2:$B$91,"PUR",'Control Matrix'!$N$2:$N$91,1) | F18: =COUNTIFS('Control Matrix'!$B$2:$B$91,"PUR",'Control Matrix'!$R$2:$R$91,1) | G18: =IF(SUMIFS('Control Matrix'!$T$2:$T$91,'Control Matrix'!$B$2:$B$91,"PUR")=0,"",SUMIFS('Control Matrix'!$S$2:$S$91,'Control Matrix'!$B$2:$B$91,"PUR")/SUMIFS('Control Matrix'!$T$2:$T$91,'Control Matrix'!$B$2:$B$91,"PUR")) | H18: =IF(G18="","",G18*C18) | I18: =IF(G18="","",C18) | J18: =IF(G18="","Not assessed",IF(G18>=0.8,"Optimised",IF(G18>=0.6,"Managed",IF(G18>=0.4,"Developing",IF(G18>=0.2,"Initial","Absent")))))
B19: NOT — Notice | C19: 1.1 | D19: =COUNTIFS('Control Matrix'!$B$2:$B$91,"NOT",'Control Matrix'!$H$2:$H$91,"Yes") | E19: =COUNTIFS('Control Matrix'!$B$2:$B$91,"NOT",'Control Matrix'!$N$2:$N$91,1) | F19: =COUNTIFS('Control Matrix'!$B$2:$B$91,"NOT",'Control Matrix'!$R$2:$R$91,1) | G19: =IF(SUMIFS('Control Matrix'!$T$2:$T$91,'Control Matrix'!$B$2:$B$91,"NOT")=0,"",SUMIFS('Control Matrix'!$S$2:$S$91,'Control Matrix'!$B$2:$B$91,"NOT")/SUMIFS('Control Matrix'!$T$2:$T$91,'Control Matrix'!$B$2:$B$91,"NOT")) | H19: =IF(G19="","",G19*C19) | I19: =IF(G19="","",C19) | J19: =IF(G19="","Not assessed",IF(G19>=0.8,"Optimised",IF(G19>=0.6,"Managed",IF(G19>=0.4,"Developing",IF(G19>=0.2,"Initial","Absent")))))
B20: CON — Consent | C20: 1.3 | D20: =COUNTIFS('Control Matrix'!$B$2:$B$91,"CON",'Control Matrix'!$H$2:$H$91,"Yes") | E20: =COUNTIFS('Control Matrix'!$B$2:$B$91,"CON",'Control Matrix'!$N$2:$N$91,1) | F20: =COUNTIFS('Control Matrix'!$B$2:$B$91,"CON",'Control Matrix'!$R$2:$R$91,1) | G20: =IF(SUMIFS('Control Matrix'!$T$2:$T$91,'Control Matrix'!$B$2:$B$91,"CON")=0,"",SUMIFS('Control Matrix'!$S$2:$S$91,'Control Matrix'!$B$2:$B$91,"CON")/SUMIFS('Control Matrix'!$T$2:$T$91,'Control Matrix'!$B$2:$B$91,"CON")) | H20: =IF(G20="","",G20*C20) | I20: =IF(G20="","",C20) | J20: =IF(G20="","Not assessed",IF(G20>=0.8,"Optimised",IF(G20>=0.6,"Managed",IF(G20>=0.4,"Developing",IF(G20>=0.2,"Initial","Absent")))))
B21: CMG — Consent Manager | C21: 0.8 | D21: =COUNTIFS('Control Matrix'!$B$2:$B$91,"CMG",'Control Matrix'!$H$2:$H$91,"Yes") | E21: =COUNTIFS('Control Matrix'!$B$2:$B$91,"CMG",'Control Matrix'!$N$2:$N$91,1) | F21: =COUNTIFS('Control Matrix'!$B$2:$B$91,"CMG",'Control Matrix'!$R$2:$R$91,1) | G21: =IF(SUMIFS('Control Matrix'!$T$2:$T$91,'Control Matrix'!$B$2:$B$91,"CMG")=0,"",SUMIFS('Control Matrix'!$S$2:$S$91,'Control Matrix'!$B$2:$B$91,"CMG")/SUMIFS('Control Matrix'!$T$2:$T$91,'Control Matrix'!$B$2:$B$91,"CMG")) | H21: =IF(G21="","",G21*C21) | I21: =IF(G21="","",C21) | J21: =IF(G21="","Not assessed",IF(G21>=0.8,"Optimised",IF(G21>=0.6,"Managed",IF(G21>=0.4,"Developing",IF(G21>=0.2,"Initial","Absent")))))
B22: LGU — Legitimate Uses | C22: 0.9 | D22: =COUNTIFS('Control Matrix'!$B$2:$B$91,"LGU",'Control Matrix'!$H$2:$H$91,"Yes") | E22: =COUNTIFS('Control Matrix'!$B$2:$B$91,"LGU",'Control Matrix'!$N$2:$N$91,1) | F22: =COUNTIFS('Control Matrix'!$B$2:$B$91,"LGU",'Control Matrix'!$R$2:$R$91,1) | G22: =IF(SUMIFS('Control Matrix'!$T$2:$T$91,'Control Matrix'!$B$2:$B$91,"LGU")=0,"",SUMIFS('Control Matrix'!$S$2:$S$91,'Control Matrix'!$B$2:$B$91,"LGU")/SUMIFS('Control Matrix'!$T$2:$T$91,'Control Matrix'!$B$2:$B$91,"LGU")) | H22: =IF(G22="","",G22*C22) | I22: =IF(G22="","",C22) | J22: =IF(G22="","Not assessed",IF(G22>=0.8,"Optimised",IF(G22>=0.6,"Managed",IF(G22>=0.4,"Developing",IF(G22>=0.2,"Initial","Absent")))))
B23: RET — Retention & Erasure | C23: 1.1 | D23: =COUNTIFS('Control Matrix'!$B$2:$B$91,"RET",'Control Matrix'!$H$2:$H$91,"Yes") | E23: =COUNTIFS('Control Matrix'!$B$2:$B$91,"RET",'Control Matrix'!$N$2:$N$91,1) | F23: =COUNTIFS('Control Matrix'!$B$2:$B$91,"RET",'Control Matrix'!$R$2:$R$91,1) | G23: =IF(SUMIFS('Control Matrix'!$T$2:$T$91,'Control Matrix'!$B$2:$B$91,"RET")=0,"",SUMIFS('Control Matrix'!$S$2:$S$91,'Control Matrix'!$B$2:$B$91,"RET")/SUMIFS('Control Matrix'!$T$2:$T$91,'Control Matrix'!$B$2:$B$91,"RET")) | H23: =IF(G23="","",G23*C23) | I23: =IF(G23="","",C23) | J23: =IF(G23="","Not assessed",IF(G23>=0.8,"Optimised",IF(G23>=0.6,"Managed",IF(G23>=0.4,"Developing",IF(G23>=0.2,"Initial","Absent")))))
B24: RGT — Data Principal Rights | C24: 1.1 | D24: =COUNTIFS('Control Matrix'!$B$2:$B$91,"RGT",'Control Matrix'!$H$2:$H$91,"Yes") | E24: =COUNTIFS('Control Matrix'!$B$2:$B$91,"RGT",'Control Matrix'!$N$2:$N$91,1) | F24: =COUNTIFS('Control Matrix'!$B$2:$B$91,"RGT",'Control Matrix'!$R$2:$R$91,1) | G24: =IF(SUMIFS('Control Matrix'!$T$2:$T$91,'Control Matrix'!$B$2:$B$91,"RGT")=0,"",SUMIFS('Control Matrix'!$S$2:$S$91,'Control Matrix'!$B$2:$B$91,"RGT")/SUMIFS('Control Matrix'!$T$2:$T$91,'Control Matrix'!$B$2:$B$91,"RGT")) | H24: =IF(G24="","",G24*C24) | I24: =IF(G24="","",C24) | J24: =IF(G24="","Not assessed",IF(G24>=0.8,"Optimised",IF(G24>=0.6,"Managed",IF(G24>=0.4,"Developing",IF(G24>=0.2,"Initial","Absent")))))
B25: GRV — Grievance Redressal | C25: 1 | D25: =COUNTIFS('Control Matrix'!$B$2:$B$91,"GRV",'Control Matrix'!$H$2:$H$91,"Yes") | E25: =COUNTIFS('Control Matrix'!$B$2:$B$91,"GRV",'Control Matrix'!$N$2:$N$91,1) | F25: =COUNTIFS('Control Matrix'!$B$2:$B$91,"GRV",'Control Matrix'!$R$2:$R$91,1) | G25: =IF(SUMIFS('Control Matrix'!$T$2:$T$91,'Control Matrix'!$B$2:$B$91,"GRV")=0,"",SUMIFS('Control Matrix'!$S$2:$S$91,'Control Matrix'!$B$2:$B$91,"GRV")/SUMIFS('Control Matrix'!$T$2:$T$91,'Control Matrix'!$B$2:$B$91,"GRV")) | H25: =IF(G25="","",G25*C25) | I25: =IF(G25="","",C25) | J25: =IF(G25="","Not assessed",IF(G25>=0.8,"Optimised",IF(G25>=0.6,"Managed",IF(G25>=0.4,"Developing",IF(G25>=0.2,"Initial","Absent")))))
B26: SEC — Security Safeguards | C26: 1.4 | D26: =COUNTIFS('Control Matrix'!$B$2:$B$91,"SEC",'Control Matrix'!$H$2:$H$91,"Yes") | E26: =COUNTIFS('Control Matrix'!$B$2:$B$91,"SEC",'Control Matrix'!$N$2:$N$91,1) | F26: =COUNTIFS('Control Matrix'!$B$2:$B$91,"SEC",'Control Matrix'!$R$2:$R$91,1) | G26: =IF(SUMIFS('Control Matrix'!$T$2:$T$91,'Control Matrix'!$B$2:$B$91,"SEC")=0,"",SUMIFS('Control Matrix'!$S$2:$S$91,'Control Matrix'!$B$2:$B$91,"SEC")/SUMIFS('Control Matrix'!$T$2:$T$91,'Control Matrix'!$B$2:$B$91,"SEC")) | H26: =IF(G26="","",G26*C26) | I26: =IF(G26="","",C26) | J26: =IF(G26="","Not assessed",IF(G26>=0.8,"Optimised",IF(G26>=0.6,"Managed",IF(G26>=0.4,"Developing",IF(G26>=0.2,"Initial","Absent")))))
B27: BRC — Personal Data Breach Notification | C27: 1.3 | D27: =COUNTIFS('Control Matrix'!$B$2:$B$91,"BRC",'Control Matrix'!$H$2:$H$91,"Yes") | E27: =COUNTIFS('Control Matrix'!$B$2:$B$91,"BRC",'Control Matrix'!$N$2:$N$91,1) | F27: =COUNTIFS('Control Matrix'!$B$2:$B$91,"BRC",'Control Matrix'!$R$2:$R$91,1) | G27: =IF(SUMIFS('Control Matrix'!$T$2:$T$91,'Control Matrix'!$B$2:$B$91,"BRC")=0,"",SUMIFS('Control Matrix'!$S$2:$S$91,'Control Matrix'!$B$2:$B$91,"BRC")/SUMIFS('Control Matrix'!$T$2:$T$91,'Control Matrix'!$B$2:$B$91,"BRC")) | H27: =IF(G27="","",G27*C27) | I27: =IF(G27="","",C27) | J27: =IF(G27="","Not assessed",IF(G27>=0.8,"Optimised",IF(G27>=0.6,"Managed",IF(G27>=0.4,"Developing",IF(G27>=0.2,"Initial","Absent")))))
B28: CHD — Children & Persons with Disability | C28: 1.2 | D28: =COUNTIFS('Control Matrix'!$B$2:$B$91,"CHD",'Control Matrix'!$H$2:$H$91,"Yes") | E28: =COUNTIFS('Control Matrix'!$B$2:$B$91,"CHD",'Control Matrix'!$N$2:$N$91,1) | F28: =COUNTIFS('Control Matrix'!$B$2:$B$91,"CHD",'Control Matrix'!$R$2:$R$91,1) | G28: =IF(SUMIFS('Control Matrix'!$T$2:$T$91,'Control Matrix'!$B$2:$B$91,"CHD")=0,"",SUMIFS('Control Matrix'!$S$2:$S$91,'Control Matrix'!$B$2:$B$91,"CHD")/SUMIFS('Control Matrix'!$T$2:$T$91,'Control Matrix'!$B$2:$B$91,"CHD")) | H28: =IF(G28="","",G28*C28) | I28: =IF(G28="","",C28) | J28: =IF(G28="","Not assessed",IF(G28>=0.8,"Optimised",IF(G28>=0.6,"Managed",IF(G28>=0.4,"Developing",IF(G28>=0.2,"Initial","Absent")))))
B29: PRO — Processors & Vendor Contracts | C29: 1.1 | D29: =COUNTIFS('Control Matrix'!$B$2:$B$91,"PRO",'Control Matrix'!$H$2:$H$91,"Yes") | E29: =COUNTIFS('Control Matrix'!$B$2:$B$91,"PRO",'Control Matrix'!$N$2:$N$91,1) | F29: =COUNTIFS('Control Matrix'!$B$2:$B$91,"PRO",'Control Matrix'!$R$2:$R$91,1) | G29: =IF(SUMIFS('Control Matrix'!$T$2:$T$91,'Control Matrix'!$B$2:$B$91,"PRO")=0,"",SUMIFS('Control Matrix'!$S$2:$S$91,'Control Matrix'!$B$2:$B$91,"PRO")/SUMIFS('Control Matrix'!$T$2:$T$91,'Control Matrix'!$B$2:$B$91,"PRO")) | H29: =IF(G29="","",G29*C29) | I29: =IF(G29="","",C29) | J29: =IF(G29="","Not assessed",IF(G29>=0.8,"Optimised",IF(G29>=0.6,"Managed",IF(G29>=0.4,"Developing",IF(G29>=0.2,"Initial","Absent")))))
B30: XBD — Cross-Border Transfers | C30: 0.9 | D30: =COUNTIFS('Control Matrix'!$B$2:$B$91,"XBD",'Control Matrix'!$H$2:$H$91,"Yes") | E30: =COUNTIFS('Control Matrix'!$B$2:$B$91,"XBD",'Control Matrix'!$N$2:$N$91,1) | F30: =COUNTIFS('Control Matrix'!$B$2:$B$91,"XBD",'Control Matrix'!$R$2:$R$91,1) | G30: =IF(SUMIFS('Control Matrix'!$T$2:$T$91,'Control Matrix'!$B$2:$B$91,"XBD")=0,"",SUMIFS('Control Matrix'!$S$2:$S$91,'Control Matrix'!$B$2:$B$91,"XBD")/SUMIFS('Control Matrix'!$T$2:$T$91,'Control Matrix'!$B$2:$B$91,"XBD")) | H30: =IF(G30="","",G30*C30) | I30: =IF(G30="","",C30) | J30: =IF(G30="","Not assessed",IF(G30>=0.8,"Optimised",IF(G30>=0.6,"Managed",IF(G30>=0.4,"Developing",IF(G30>=0.2,"Initial","Absent")))))
B31: SDF — Significant Data Fiduciary Obligations | C31: 1.2 | D31: =COUNTIFS('Control Matrix'!$B$2:$B$91,"SDF",'Control Matrix'!$H$2:$H$91,"Yes") | E31: =COUNTIFS('Control Matrix'!$B$2:$B$91,"SDF",'Control Matrix'!$N$2:$N$91,1) | F31: =COUNTIFS('Control Matrix'!$B$2:$B$91,"SDF",'Control Matrix'!$R$2:$R$91,1) | G31: =IF(SUMIFS('Control Matrix'!$T$2:$T$91,'Control Matrix'!$B$2:$B$91,"SDF")=0,"",SUMIFS('Control Matrix'!$S$2:$S$91,'Control Matrix'!$B$2:$B$91,"SDF")/SUMIFS('Control Matrix'!$T$2:$T$91,'Control Matrix'!$B$2:$B$91,"SDF")) | H31: =IF(G31="","",G31*C31) | I31: =IF(G31="","",C31) | J31: =IF(G31="","Not assessed",IF(G31>=0.8,"Optimised",IF(G31>=0.6,"Managed",IF(G31>=0.4,"Developing",IF(G31>=0.2,"Initial","Absent")))))
B32: BRD — Enforcement Readiness & Board Engagement | C32: 0.7 | D32: =COUNTIFS('Control Matrix'!$B$2:$B$91,"BRD",'Control Matrix'!$H$2:$H$91,"Yes") | E32: =COUNTIFS('Control Matrix'!$B$2:$B$91,"BRD",'Control Matrix'!$N$2:$N$91,1) | F32: =COUNTIFS('Control Matrix'!$B$2:$B$91,"BRD",'Control Matrix'!$R$2:$R$91,1) | G32: =IF(SUMIFS('Control Matrix'!$T$2:$T$91,'Control Matrix'!$B$2:$B$91,"BRD")=0,"",SUMIFS('Control Matrix'!$S$2:$S$91,'Control Matrix'!$B$2:$B$91,"BRD")/SUMIFS('Control Matrix'!$T$2:$T$91,'Control Matrix'!$B$2:$B$91,"BRD")) | H32: =IF(G32="","",G32*C32) | I32: =IF(G32="","",C32) | J32: =IF(G32="","Not assessed",IF(G32>=0.8,"Optimised",IF(G32>=0.6,"Managed",IF(G32>=0.4,"Developing",IF(G32>=0.2,"Initial","Absent")))))
B33: TOTAL / WEIGHTED | D33: =SUM(D16:D32) | E33: =SUM(E16:E32) | F33: =SUM(F16:F32) | G33: =IF(SUM(I16:I32)=0,"",SUM(H16:H32)/SUM(I16:I32))
B36: STATUS SUMMARY
B37: Compliant | C37: =COUNTIFS('Control Matrix'!$O$2:$O$91,"Compliant")
B38: Substantially compliant | C38: =COUNTIFS('Control Matrix'!$O$2:$O$91,"Substantially compliant")
B39: Partially compliant | C39: =COUNTIFS('Control Matrix'!$O$2:$O$91,"Partially compliant")
B40: Non-compliant | C40: =COUNTIFS('Control Matrix'!$O$2:$O$91,"Non-compliant")
B41: Not assessed | C41: =COUNTIFS('Control Matrix'!$O$2:$O$91,"Not assessed")
B42: Not applicable | C42: =COUNTIFS('Control Matrix'!$O$2:$O$91,"Not applicable")
B43: Out of scope | C43: =COUNTIFS('Control Matrix'!$O$2:$O$91,"Out of scope")
B45: GAPS BY SEVERITY
B46: Critical | C46: =COUNTIFS('Control Matrix'!$R$2:$R$91,1,'Control Matrix'!$E$2:$E$91,"Critical")
B47: High | C47: =COUNTIFS('Control Matrix'!$R$2:$R$91,1,'Control Matrix'!$E$2:$E$91,"High")
...

Sheet Company Profile
B2: Company Profile & Engagement Details
B3: Yellow cells are inputs. Applicability flags determine which controls are in scope.
B5: ENTITY
B6: Legal name | C6: Kavach Financial Technologies Private Limited
B7: Trading name | C7: KavachPay
B8: Sector | C8: Financial services — consumer lending, UPI payments and prepaid instruments
B9: Registered office | C9: Level 7, Prestige Zeta, Whitefield Main Road, Bengaluru 560066, Karnataka, India
B10: Headcount | C10: 1180
B11: Data Principals (approx.) | C11: 14200000
B12: Business description | C12: KavachPay operates a consumer financial services platform in India comprising a UPI payments application, an unsecured personal and consumer-durable lending business originated digitally and co-lent with two partner NBFCs, a prepaid payment instrument wallet, and 'Kavach Junior', a supervised prepaid card and savings product marketed to 13-17 year olds under a parent's account. Onboarding is fully digital and relies on third-party KYC and bureau services. The entity was notified as a Significant Data Fiduciary and participates in the account aggregator ecosystem as a Financial Information User, receiving financial information through a registered Consent Manager.
B14: ENGAGEMENT
B15: Assessment date | C15: 2026-08-14
B16: Auditor | C16: Nandita Krishnan, CIPP/E, CISA
B17: Firm | C17: Sentinel Assurance LLP, Chartered Accountants
B18: Engagement reference | C18: SA/DPDP/2026/0417
B19: Scope statement | C19: An assessment of the design and operating effectiveness of the entity's arrangements for compliance with the Digital Personal Data Protection Act, 2023 across the digital personal data processing activities of Kavach Financial Technologies Private Limited and its collections subsidiary, covering the systems and activities listed in the scope schedule. Fieldwork was performed between 27 July and 14 August 2026 and comprised document inspection, 19 process walkthroughs with control owners, inspection of system configuration, and substantive testing of consent, withdrawal, rights and erasure journeys on live and non-production environments.
B21: APPLICABILITY FLAGS
B22: Flag | C22: Value | D22: Meaning
B23: is_sdf | C23: Yes | D23: Notified by the Central Government as a Significant Data Fiduciary under s.10(1). Set True only on actual notification, not on self-assessment.
B24: processes_children_data | C24: Yes | D24: Processes personal data of individuals under 18, or of persons with a lawful guardian. Defaults True because age is rarely reliably excluded.
B25: processes_employee_data | C25: Yes | D25: Processes personal data of employees, workers or contractors.
B26: uses_consent_manager | C26: Yes | D26: Receives or manages consent through a registered Consent Manager under s.6(7).
B27: is_consent_manager | C27: No | D27: The entity itself acts as a Consent Manager and requires registration under s.6(8).
B28: has_pre_commencement_data | C28: Yes | D28: Holds personal data processed on the basis of consent given before commencement, engaging the retrospective notice duty under s.5(2).
B29: regulated_sector | C29: Yes | D29: Subject to sectoral regulation that may impose stricter localisation or transfer requirements preserved by s.16(2) — banking, payments, insurance, telecom, securities, health.
B30: claims_exemption | C30: No | D30: Claims any exemption under s.17, including the class-based route in s.17(3).
B31: startup_exempt_s8_3 | C31: No | D31: Exempt from s.8(3) as a notified class under s.17(3). Requires actual notification.
B32: startup_exempt_s8_7 | C32: No | D32: Exempt from s.8(7) as a notified class under s.17(3). Requires actual notification.
B33: startup_exempt_s11 | C33: No | D33: Exempt from s.11 as a notified class under s.17(3). Requires actual notification.
B35: Note: changing a flag here does not re-filter the Control Matrix. Update the profile in the toolkit and regenerate, so that scope changes are recorded in the assessment file rather than only in the workbook.

Sheet Instructions
B2: DPDPA Compliance Audit — Control Matrix Workbook
B3: Digital Personal Data Protection Act, 2023 · control library v1.0.0 · 90 controls across 17 domains
B6: HOW TO USE THIS WORKBOOK
B7: Live model | C7: This is a working model, not a static export. The Score column on the Control Matrix is the only scoring input. Risk, status, gap flags, domain maturity, the overall score and the penalty-exposure table are formulas and update as soon as a score changes.
B8: Cells to edit | C8: Yellow cells only. On the Control Matrix these are Score (M), Finding (U), Evidence ref (V), Owner (W) and Target date (X). On Company Profile they are the value column. Every other cell is either reference text from the control library or a formula — overwriting a formula will break the dashboard.
B9: Scoring scale | C9: The library defines anchored descriptors for 0, 2 and 4; 1 and 3 are intermediate positions. Score the position you can evidence, not the intent. 0 = Absent — no capability · 1 = Initial — ad hoc, undocumented · 2 = Developing — partial, inconsistent · 3 = Managed — substantially in place, minor gaps · 4 = Optimised — complete, evidenced, tested
B10: Not applicable | C10: Enter NA where a control genuinely cannot apply. NA removes the control from the denominator. Do not score an inapplicable control 0 — that understates maturity and manufactures a gap that cannot be remediated.
B11: Out of scope | C11: Controls shown as In scope = No were excluded automatically by the applicability flags on the Company Profile sheet, with the reason given in column I. Change a flag and regenerate from the toolkit to bring them into scope.
B12: Gap threshold | C12: A control scoring below 3 of 4 is reported as a gap. 3 is the 'substantially in place, minor gaps' anchor, so the register captures every control where the obligation could not be concluded met.
B13: Risk score | C13: Risk = severity rank × (4 − score), range 0 to 16. Severity ranks are critical 4, high 3, medium 2, low 1. Risk therefore reflects both the seriousness of the obligation and how far short the entity falls. Bands: 12+ Critical, 8-11 High, 4-7 Medium, 1-3 Low.
B15: CITATIONS — READ THIS
B16: Act references | C16: Column J cites the DPDP Act, 2023. These are stated with confidence.
B17: Rules references | C17: Column K shows '[Rules citation to be verified]' wherever the rule number was not available when the library was authored. This is deliberate: a wrong statutory citation in a signed report passes review and reaches the regulator, whereas a blank one does not. Populate controls/citations.yaml once and every output updates. The Citations sheet lists each outstanding slot.
B18: Commencement | C18: The commencement position of individual provisions was not confirmed. Findings are compliance gaps against the framework as a whole; do not characterise a gap as a contravention of a provision without first confirming that it is in force.
B20: PENALTY EXPOSURE
B21: What it shows | C21: The Dashboard aggregates the statutory maxima under the Schedule to the Act for those entries engaged by controls currently scored below the gap threshold.
B22: What it is not | C22: It is a ceiling, not a prediction. Section 33(2) requires the Board to have regard to gravity, duration, the data affected, proportionality and mitigating action. Any penalty actually imposed would be a fraction of the ceiling, and documented prompt remediation is an express mitigating factor.
B24: LEGEND
B25: Yellow fill | C25: Input cell — edit this
B26: White / grey | C26: Reference text or formula — do not overwrite

Sheet Control Matrix
A1: Control ID | B1: Domain | C1: Domain name | D1: Control title | E1: Severity | F1: Sev rank | G1: Weight | H1: In scope | I1: Scope reason | J1: Act reference | K1: Rules reference | L1: Rules status | M1: Score (0-4 / NA) | N1: Scored | O1: Status | P1: Risk | Q1: Risk band | R1: Gap | S1: Contribution | T1: Max contribution | U1: Finding | V1: Evidence ref | W1: Owner | X1: Target date | Y1: Obligation | Z1: Audit question | AA1: Test procedure | AB1: Evidence expected | AC1: Penalty exposure | AD1: Penalty entry | AE1: Required target state (level 4)
A2: APP-01 | B2: APP | C2: Applicability & Role Determination | D2: Territorial and material applicability assessed | E2: High | F2: =IF(E2="Critical",4,IF(E2="High",3,IF(E2="Medium",2,1))) | G2: 1.2 | H2: Yes | I2: in scope | J2: s.3(a), s.3(b), DPDP Act, 2023 | K2: — | L2: — | M2: 3 | N2: =IF(OR(H2="No",M2="",UPPER(M2)="NA"),0,1) | O2: =IF(H2="No","Out of scope",IF(UPPER(M2)="NA","Not applicable",IF(M2="","Not assessed",IF(M2>=4,"Compliant",IF(M2>=3,"Substantially compliant",IF(M2>=2,"Partially compliant","Non-compliant")))))) | P2: =IF(N2=0,"",F2*(4-M2)) | Q2: =IF(P2="","",IF(P2>=12,"Critical",IF(P2>=8,"High",IF(P2>=4,"Medium",IF(P2>=1,"Low","None"))))) | R2: =IF(AND(N2=1,M2<3),1,0) | S2: =IF(N2=0,"",M2*G2) | T2: =IF(N2=0,"",4*G2) | U2: A written applicability analysis dated 12 February 2026 concludes that the entity processes digital personal data within India as a Data Fiduciary and additionally offers goods and services to Data Principals in India from a Singapore-incorporated affiliate. The analysis is sound but has not been revisited since the Kavach Junior launch in April 2026. | V2: WP-001 | W2: Meera Raghunathan, Head of Legal & Compliance | Y2: The Act applies to processing of digital personal data within India, and to processing outside India where it is in connection with any activity related to offering goods or services to Data Principals within India. The entity must have determined, and be able to explain, why the Act applies to it and to which processing activities. | Z2: Has the entity documented a reasoned applicability assessment covering both India-based processing and any offshore processing connected with offering goods or services into India? Does it correctly treat personal data collected in non-digital form and subsequently digitised as in scope? | AA2: Inspect the applicability assessment; enquire of legal/privacy owner; corroborate against the entity's actual product footprint and entity structure. | AB2: Written applicability assessment or scoping memorandum, dated and owned · List of legal entities, branches and offshore affiliates that process personal data of individuals in India · Confirmation of treatment of digitised paper records | AC2: Up to INR 50 crore | AD2: 7 | AE2: A documented, dated and reviewed assessment covers all entities and processing activities, correctly addresses extraterritorial reach and digitised records, and is refreshed when the product or entity footprint changes.
A3: APP-02 | B3: APP | C3: Applicability & Role Determination | D3: Role determination — Data Fiduciary versus Data Processor | E3: Critical | F3: =IF(E3="Critical",4,IF(E3="High",3,IF(E3="Medium",2,1))) | G3: 1.3 | H3: Yes | I3: in scope | J3: s.2, DPDP Act, 2023 (definitions of "Data Fiduciary", "Data Processor" and "Data Principal"), read with s.8(1) | K3: — | L3: — | M3: 2 | N3: =IF(OR(H3="No",M3="",UPPER(M3)="NA"),0,1) | O3: =IF(H3="No","Out of scope",IF(UPPER(M3)="NA","Not applicable",IF(M3="","Not assessed",IF(M3>=4,"Compliant",IF(M3>=3,"Substantially compliant",IF(M3>=2,"Partially compliant","Non-compliant")))))) | P3: =IF(N3=0,"",F3*(4-M3)) | Q3: =IF(P3="","",IF(P3>=12,"Critical",IF(P3>=8,"High",IF(P3>=4,"Medium",IF(P3>=1,"Low","None"))))) | R3: =IF(AND(N3=1,M3<3),1,0) | S3: =IF(N3=0,"",M3*G3) | T3: =IF(N3=0,"",4*G3) | U3: Role determination has been performed for the co-lending arrangements and for the KYC vendors, but not for the marketing stack. CleverTap and the Meta Custom Audiences integration are treated as processors in the vendor register while the contractual terms and the practical control over onward use point to an independent fiduciary role for the advertising platforms. The mischaracterisation understates the notice and consent obligations attaching to those disclosures. | V3: WP-002 | W3: Meera Raghunathan, Head of Legal & Compliance | Y3: The entity must correctly determine, for each processing activity, whether it acts as a Data Fiduciary (alone or jointly), determining the purpose and means of processing, or as a Data Processor acting on another's behalf. | Z3: Is there an activity-level role mapping? Where the entity claims to be only a Data Processor, does the evidence support that it does not determine purpose or means — including for any analytics, product improvement, model training or marketing it performs on the same data? | AA3: Inspect role mapping; re-perform the determination for a sample of three activities, testing the claim against contracts and actual data use. | AB3: Activity-level register recording role assumed and the basis for it · Customer or client contracts supporting a processor characterisation · Evidence that no independent purposes are pursued on processor-held data | AC3: Up to INR 50 crore | AD3: 7 | AE3: Roles are determined per activity, documented with reasoning, consistent with contracts and observed data flows, and re-tested when new uses such as model training are introduced.
A4: APP-03 | B4: APP | C4: Applicability & Role Determination | D4: Exemptions claimed are valid and evidenced | E4: High | F4: =IF(E4="Critical",4,IF(E4="High",3,IF(E4="Medium",2,1))) | G4: 1 | H4: No | I4: requires claims_exemption | J4: s.17(1), s.17(2), s.17(3), s.17(4), DPDP Act, 2023 | K4: [Rules citation to be verified] | L4: VERIFY_AGAINST_NOTIFIED_RULES | N4: =IF(OR(H4="No",M4="",UPPER(M4)="NA"),0,1) | O4: =IF(H4="No","Out of scope",IF(UPPER(M4)="NA","Not applicable",IF(M4="","Not assessed",IF(M4>=4,"Compliant",IF(M4>=3,"Substantially compliant",IF(M4>=2,"Partially compliant","Non-compliant")))))) | P4: =IF(N4=0,"",F4*(4-M4)) | Q4: =IF(P4="","",IF(P4>=12,"Critical",IF(P4>=8,"High",IF(P4>=4,"Medium",IF(P4>=1,"Low","None"))))) | R4: =IF(AND(N4=1,M4<3),1,0) | S4: =IF(N4=0,"",M4*G4) | T4: =IF(N4=0,"",4*G4) | Y4: Exemptions under section 17 apply only in the circumstances specified. The startup and class-based exemption under section 17(3) operates only in favour of classes of Data Fiduciary actually notified by the Central Government, and covers only the specified provisions. | Z4: Does the entity claim any exemption? If it claims the section 17(3) route, can it show that it falls within a class actually notified, rather than relying on self-identification as a startup? Is the claim limited to the provisions the exemption actually reaches? | AA4: Inspect the exemption claim and supporting notification; test the scope claimed against the provisions the exemption covers. | AB4: Written exemption analysis identifying the specific limb relied upon · Evidence of falling within a notified class, where section 17(3) is relied upon · Confirmation that obligations outside the exemption's scope continue to be met | AC4: Up to INR 50 crore | AD4: 7 | AE4: Either no exemption is claimed, or the claim is narrowly scoped, evidenced against a notified class, and obligations outside its reach are demonstrably still met.
A5: APP-04 | B5: APP | C5: Applicability & Role Determination | D5: Significant Data Fiduciary exposure assessed | E5: Medium | F5: =IF(E5="Critical",4,IF(E5="High",3,IF(E5="Medium",2,1))) | G5: 0.9 | H5: No | I5: excluded by is_sdf | J5: s.10(1), DPDP Act, 2023 | K5: — | L5: — | N5: =IF(OR(H5="No",M5="",UPPER(M5)="NA"),0,1) | O5: =IF(H5="No","Out of scope",IF(UPPER(M5)="NA","Not applicable",IF(M5="","Not assessed",IF(M5>=4,"Compliant",IF(M5>=3,"Substantially compliant",IF(M5>=2,"Partially compliant","Non-compliant")))))) | P5: =IF(N5=0,"",F5*(4-M5)) | Q5: =IF(P5="","",IF(P5>=12,"Critical",IF(P5>=8,"High",IF(P5>=4,"Medium",IF(P5>=1,"Low","None"))))) | R5: =IF(AND(N5=1,M5<3),1,0) | S5: =IF(N5=0,"",M5*G5) | T5: =IF(N5=0,"",4*G5) | Y5: The Central Government may notify a Data Fiduciary or class of Data Fiduciaries as Significant, having regard to the volume and sensitivity of personal data processed, risk to the rights of Data Principals, potential effects on the sovereignty and integrity of India, risk to electoral democracy, security of the State and public order. | Z5: Has the entity assessed its likelihood of designation against the section 10(1) factors, and does it have a plan to stand up section 10(2) capability within a realistic period of being notified? | AA5: Inspect the self-assessment against each statutory factor; enquire as to readiness planning. | AB5: Self-assessment against each of the section 10(1) factors · Readiness plan for DPO appointment, DPIA, independent audit and algorithmic due diligence · Board or management minute acknowledging the exposure | AC5: — | AE5: A documented assessment against each factor exists, is periodically refreshed, and a costed readiness plan is approved so that designation would not require a standing start.
A6: APP-05 | B6: APP | C6: Applicability & Role Determination | D6: Commencement and phasing tracked against the compliance plan | E6: High | F6: =IF(E6="Critical",4,IF(E6="High",3,IF(E6="Medium",2,1))) | G6: 1.1 | H6: Yes | I6: in scope | J6: s.1(2), DPDP Act, 2023 | K6: [Rules citation to be verified] | L6: VERIFY_AGAINST_NOTIFIED_RULES | M6: 1 | N6: =IF(OR(H6="No",M6="",UPPER(M6)="NA"),0,1) | O6: =IF(H6="No","Out of scope",IF(UPPER(M6)="NA","Not applicable",IF(M6="","Not assessed",IF(M6>=4,"Compliant",IF(M6>=3,"Substantially compliant",IF(M6>=2,"Partially compliant","Non-compliant")))))) | P6: =IF(N6=0,"",F6*(4-M6)) | Q6: =IF(P6="","",IF(P6>=12,"Critical",IF(P6>=8,"High",IF(P6>=4,"Medium",IF(P6>=1,"Low","None"))))) | R6: =IF(AND(N6=1,M6<3),1,0) | S6: =IF(N6=0,"",M6*G6) | T6: =IF(N6=0,"",4*G6) | U6: The compliance plan carries a single milestone described as 'DPDP readiness' with no linkage to the commencement of individual provisions or to the phasing of the Rules. Management could not demonstrate a mechanism for tracking notifications, so a provision coming into force would not automatically trigger a change in the plan. | V6: WP-003 | W6: Meera Raghunathan, Head of Legal & Compliance | Y6: Provisions of the Act and the Rules come into force on such dates as are appointed, which may differ across provisions. The entity must know which obligations are presently enforceable and which are forthcoming. | Z6: Does the entity maintain a current view of which provisions are in force, with its remediation plan sequenced against those dates rather than against an assumption that everything is either live or not yet live? | AA6: Inspect the compliance calendar; corroborate the dates recorded against the commencement notification. | AB6: Compliance calendar mapping obligations to commencement dates · Remediation plan sequenced against those dates · Evidence of monitoring for further notifications | AC6: — | AE6: A maintained calendar tracks each tranche, remediation is sequenced against it, and a named owner monitors for further notifications and Board guidance.
A7: GOV-01 | B7: GOV | C7: Governance, Accountability & Records | D7: Accountability for compliance, including processor activity | E7: Critical | F7: =IF(E7="Critical",4,IF(E7="High",3,IF(E7="Medium",2,1))) | G7: 1.3 | H7: Yes | I7: in scope | J7: s.8(1), DPDP Act, 2023 | K7: — | L7: — | M7: 2 | N7: =IF(OR(H7="No",M7="",UPPER(M7)="NA"),0,1) | O7: =IF(H7="No","Out of scope",IF(UPPER(M7)="NA","Not applicable",IF(M7="","Not assessed",IF(M7>=4,"Compliant",IF(M7>=3,"Substantially compliant",IF(M7>=2,"Partially compliant","Non-compliant")))))) | P7: =IF(N7=0,"",F7*(4-M7)) | Q7: =IF(P7="","",IF(P7>=12,"Critical",IF(P7>=8,"High",IF(P7>=4,"Medium",IF(P7>=1,"Low","None"))))) | R7: =IF(AND(N7=1,M7<3),1,0) | S7: =IF(N7=0,"",M7*G7) | T7: =IF(N7=0,"",4*G7) | U7: Accountability is asserted in the Information Privacy Policy v2.1 and the Head of Legal & Compliance is named as owner. However the policy is silent on the entity's responsibility for processing carried out by processors on its behalf, and the collections subsidiary operates its own dialler and call recording estate without the parent's oversight of that processing. | V7: WP-010 | W7: Meera Raghunathan, Head of Legal & Compliance | Y7: A Data Fiduciary is responsible for complying with the Act in respect of any processing undertaken by it or on its behalf by a Data Processor, notwithstanding any agreement to the contrary or the Data Principal's failure to carry out their duties. | Z7: Is there a named, senior accountable owner for DPDPA compliance whose remit expressly extends to processing carried out by processors, with sufficient authority and resourcing to act? | AA7: Inspect the appointment and remit; enquire of the owner as to authority, budget and escalation path; corroborate with governance minutes. | AB7: Written appointment recording name, role and remit · Governance forum terms of reference and minutes evidencing oversight · Evidence of resourcing and of escalation to senior management or the board | AC7: Up to INR 50 crore | AD7: 7 | AE7: A senior owner is formally appointed with an express remit covering processors, reports periodically to a governance forum or the board, and can evidence decisions actually taken under that authority.
A8: GOV-02 | B8: GOV | C8: Governance, Accountability & Records | D8: Record of processing activities maintained | E8: Critical | F8: =IF(E8="Critical",4,IF(E8="High",3,IF(E8="Medium",2,1))) | G8: 1.3 | H8: Yes | I8: in scope | J8: s.6(10), s.8(1), DPDP Act, 2023 (evidential requirement) | K8: — | L8: — | M8: 2 | N8: =IF(OR(H8="No",M8="",UPPER(M8)="NA"),0,1) | O8: =IF(H8="No","Out of scope",IF(UPPER(M8)="NA","Not applicable",IF(M8="","Not assessed",IF(M8>=4,"Compliant",IF(M8>=3,"Substantially compliant",IF(M8>=2,"Partially compliant","Non-compliant")))))) | P8: =IF(N8=0,"",F8*(4-M8)) | Q8: =IF(P8="","",IF(P8>=12,"Critical",IF(P8>=8,"High",IF(P8>=4,"Medium",IF(P8>=1,"Low","None"))))) | R8: =IF(AND(N8=1,M8<3),1,0) | S8: =IF(N8=0,"",M8*G8) | T8: =IF(N8=0,"",4*G8) | U8: A record of processing activities exists in a spreadsheet covering 61 activities, last updated November 2025. Walkthroughs identified four unrecorded processing activities: Kavach Junior parent supervision, the WhatsApp collections journey, the churn-prediction model in Kavach Analytics, and employee productivity monitoring in the collections function. The record does not capture retention period or recipient for 23 of the 61 entries. | V8: WP-011 | W8: Meera Raghunathan, Head of Legal & Compliance | Y8: Although the Act does not name a register in terms, the burden of demonstrating consent under section 6(10) and the accountability duty under section 8(1) cannot be discharged without a reliable record of what personal data is processed, for what purpose, on what basis, and with whom it is shared. | Z8: Is there a complete, current record of processing activities capturing data categories, purposes, lawful basis, retention, recipients, processors and cross-border flows? Is it reconciled to reality rather than maintained as a one-off documentation exercise? | AA8: Inspect the register; test completeness by selecting two systems not obviously covered and tracing them; test currency against recent product changes. | AB8: Record of processing activities with the fields above · Evidence of periodic review with dates and reviewer · Reconciliation to a system or application inventory | AC8: Up to INR 50 crore | AD8: 7 | AE8: A complete register is reconciled to the application inventory, refreshed on a defined cycle and on material change, and demonstrably drives downstream artefacts such as notices and retention rules.
A9: GOV-03 | B9: GOV | C9: Governance, Accountability & Records | D9: Publication of DPO or contact person details | E9: High | F9: =IF(E9="Critical",4,IF(E9="High",3,IF(E9="Medium",2,1))) | G9: 1 | H9: Yes | I9: in scope | J9: s.8(8), DPDP Act, 2023 | K9: [Rules citation to be verified] | L9: VERIFY_AGAINST_NOTIFIED_RULES | M9: 3 | N9: =IF(OR(H9="No",M9="",UPPER(M9)="NA"),0,1) | O9: =IF(H9="No","Out of scope",IF(UPPER(M9)="NA","Not applicable",IF(M9="","Not assessed",IF(M9>=4,"Compliant",IF(M9>=3,"Substantially compliant",IF(M9>=2,"Partially compliant","Non-compliant")))))) | P9: =IF(N9=0,"",F9*(4-M9)) | Q9: =IF(P9="","",IF(P9>=12,"Critical",IF(P9>=8,"High",IF(P9>=4,"Medium",IF(P9>=1,"Low","None"))))) | R9: =IF(AND(N9=1,M9<3),1,0) | S9: =IF(N9=0,"",M9*G9) | T9: =IF(N9=0,"",4*G9) | U9: Contact details for the privacy function are published in the app privacy policy and on the website footer, and the address routes to a monitored mailbox. The published contact is a generic role address rather than the person discharging the function, and the Kavach Junior parent console does not surface the contact at all. | V9: WP-012 | W9: Meera Raghunathan, Head of Legal & Compliance | Y9: A Data Fiduciary must publish the business contact information of the Data Protection Officer, if applicable, or of a person able to answer on its behalf the questions of a Data Principal about the processing of their personal data. | Z9: Are contact details published in a place a Data Principal would actually find them, and does a real, monitored channel sit behind them that is capable of answering substantive questions about processing? | AA9: Inspect the published details on all customer-facing surfaces; re-perform by sending a substantive processing question through the channel and measuring the response. | AB9: Screenshots of published contact details on website, app and other surfaces · Evidence of channel monitoring and ownership · Sample of substantive questions received and answered | AC9: Up to INR 50 crore | AD9: 7 | AE9: Details are prominently and consistently published across all surfaces, the channel is monitored with defined ownership and service levels, and testing shows substantive questions are answered competently.
A10: GOV-04 | B10: GOV | C10: Governance, Accountability & Records | D10: Board and senior management oversight | E10: Medium | F10: =IF(E10="Critical",4,IF(E10="High",3,IF(E10="Medium",2,1))) | G10: 1 | H10: Yes | I10: in scope | J10: s.8(1), s.10(2)(a), DPDP Act, 2023 | K10: — | L10: — | M10: 2 | N10: =IF(OR(H10="No",M10="",UPPER(M10)="NA"),0,1) | O10: =IF(H10="No","Out of scope",IF(UPPER(M10)="NA","Not applicable",IF(M10="","Not assessed",IF(M10>=4,"Compliant",IF(M10>=3,"Substantially compliant",IF(M10>=2,"Partially compliant","Non-compliant")))))) | P10: =IF(N10=0,"",F10*(4-M10)) | Q10: =IF(P10="","",IF(P10>=12,"Critical",IF(P10>=8,"High",IF(P10>=4,"Medium",IF(P10>=1,"Low","None"))))) | R10: =IF(AND(N10=1,M10<3),1,0) | S10: =IF(N10=0,"",M10*G10) | T10: =IF(N10=0,"",4*G10) | U10: Privacy is reported to the Risk Management Committee twice yearly as part of a combined information security update. Minutes for the two meetings in the period record no privacy-specific decision, no budget approval and no challenge from members. There is no board-level acceptance of the residual risk arising from the open items in this report. | V10: WP-013 | W10: Vikram Shetty, Chief Financial Officer | Y10: Accountability under section 8(1) requires oversight proportionate to the risk. For a Significant Data Fiduciary the Data Protection Officer is expressly required to be responsible to the board of directors or similar governing body, which sets the expected standard of engagement. | Z10: Does the board or an equivalent governing body receive periodic reporting on data protection risk, breaches, rights-request volumes and remediation progress, and is there evidence of it directing action? | AA10: Inspect minutes and reporting packs for the last four cycles; test whether reported issues were tracked to closure. | AB10: Board or committee minutes referencing data protection matters · Management information pack showing metrics reported · Evidence of decisions taken and tracked to closure | AC10: — | AE10: Periodic reporting on a defined cycle with meaningful metrics, evidenced challenge from the forum, and issues tracked to closure.
A11: GOV-05 | B11: GOV | C11: Governance, Accountability & Records | D11: Policies, standards and internal procedures | E11: Medium | F11: =IF(E11="Critical",4,IF(E11="High",3,IF(E11="Medium",2,1))) | G11: 1 | H11: Yes | I11: in scope | J11: s.8(4), DPDP Act, 2023 | K11: — | L11: — | M11: 3 | N11: =IF(OR(H11="No",M11="",UPPER(M11)="NA"),0,1) | O11: =IF(H11="No","Out of scope",IF(UPPER(M11)="NA","Not applicable",IF(M11="","Not assessed",IF(M11>=4,"Compliant",IF(M11>=3,"Substantially compliant",IF(M11>=2,"Partially compliant","Non-compliant")))))) | P11: =IF(N11=0,"",F11*(4-M11)) | Q11: =IF(P11="","",IF(P11>=12,"Critical",IF(P11>=8,"High",IF(P11>=4,"Medium",IF(P11>=1,"Low","None"))))) | R11: =IF(AND(N11=1,M11<3),1,0) | S11: =IF(N11=0,"",M11*G11) | T11: =IF(N11=0,"",4*G11) | U11: A policy set comprising an Information Privacy Policy, Data Classification Standard, Retention Standard and Third Party Standard is approved and accessible on the intranet. The Retention Standard is dated 2023 and predates both the Kavach Junior product and the current warehouse architecture, and the Third Party Standard does not address the s.8(2) contract requirement. | V11: WP-014 | W11: Meera Raghunathan, Head of Legal & Compliance | Y11: Appropriate technical and organisational measures under section 8(4) include the documented policies and procedures by which the entity gives effect to its obligations. | Z11: Is there an approved policy set covering notice, consent, rights handling, retention, breach response, vendor management and children's data, mapped to the Act, version-controlled and actually reflected in operational procedure? | AA11: Inspect the policy set and approval records; test one policy against the operational procedure and system behaviour it purports to govern. | AB11: Approved policy set with version history and approver · Mapping of policies to Act provisions · Operational procedures or runbooks referenced by the policies | AC11: Up to INR 50 crore | AD11: 7 | AE11: An approved, version-controlled, Act-mapped policy set is in force, supported by operational runbooks, and testing confirms practice follows the documented procedure.
A12: GOV-06 | B12: GOV | C12: Governance, Accountability & Records | D12: Training and awareness | E12: Medium | F12: =IF(E12="Critical",4,IF(E12="High",3,IF(E12="Medium",2,1))) | G12: 0.9 | H12: Yes | I12: in scope | J12: s.8(4), DPDP Act, 2023 | K12: — | L12: — | M12: 2 | N12: =IF(OR(H12="No",M12="",UPPER(M12)="NA"),0,1) | O12: =IF(H12="No","Out of scope",IF(UPPER(M12)="NA","Not applicable",IF(M12="","Not assessed",IF(M12>=4,"Compliant",IF(M12>=3,"Substantially compliant",IF(M12>=2,"Partially compliant","Non-compliant")))))) | P12: =IF(N12=0,"",F12*(4-M12)) | Q12: =IF(P12="","",IF(P12>=12,"Critical",IF(P12>=8,"High",IF(P12>=4,"Medium",IF(P12>=1,"Low","None"))))) | R12: =IF(AND(N12=1,M12<3),1,0) | S12: =IF(N12=0,"",M12*G12) | T12: =IF(N12=0,"",4*G12) | U12: Annual information security training is mandatory and completion stands at 94 per cent. Privacy content within it runs to four slides and does not address consent, rights handling or the children's provisions. No role-specific training has been delivered to the engineering, marketing or collections teams whose decisions determine compliance in practice. | V12: WP-015 | W12: Sneha Kulkarni, Head of People | Y12: Organisational measures under section 8(4) extend to ensuring that personnel handling personal data understand their obligations, particularly those operating consent, rights and breach processes. | Z12: Have personnel in roles that touch personal data received DPDPA-specific training, with role-tailored content for high-risk functions such as support, marketing, engineering and procurement, and is completion tracked? | AA12: Inspect training content and completion records; enquire of a sample of staff in high-risk roles to test practical understanding. | AB12: Training material specific to the Act, not generic privacy content · Completion records by role with dates · Role-specific modules for support, marketing, engineering and procurement | AC12: — | AE12: Act-specific training is delivered to all relevant personnel with role-tailored modules for high-risk functions, completion is tracked and enforced, and sample enquiry confirms practical understanding.
A13: GOV-07 | B13: GOV | C13: Governance, Accountability & Records | D13: Evidence retention for demonstrating compliance | E13: Critical | F13: =IF(E13="Critical",4,IF(E13="High",3,IF(E13="Medium",2,1))) | G13: 1.2 | H13: Yes | I13: in scope | J13: s.6(10), DPDP Act, 2023 | K13: — | L13: — | M13: 1 | N13: =IF(OR(H13="No",M13="",UPPER(M13)="NA"),0,1) | O13: =IF(H13="No","Out of scope",IF(UPPER(M13)="NA","Not applicable",IF(M13="","Not assessed",IF(M13>=4,"Compliant",IF(M13>=3,"Substantially compliant",IF(M13>=2,"Partially compliant","Non-compliant")))))) | P13: =IF(N13=0,"",F13*(4-M13)) | Q13: =IF(P13="","",IF(P13>=12,"Critical",IF(P13>=8,"High",IF(P13>=4,"Medium",IF(P13>=1,"Low","None"))))) | R13: =IF(AND(N13=1,M13<3),1,0) | S13: =IF(N13=0,"",M13*G13) | T13: =IF(N13=0,"",4*G13) | U13: Evidence of compliance is not systematically retained. Consent artefacts are held only in the current state of the consent table with no immutable history, notice versions are not archived, and rights request correspondence is held in agent mailboxes. The entity could not reconstruct, for a Data Principal who consented in March 2025, what notice they were shown. This directly undermines the ability to discharge the burden of proof the Act places on the Data Fiduciary. | V13: WP-016 | W13: Devika Iyer, VP Engineering | Y13: Where consent is relied upon, the Data Fiduciary bears the burden of proving that notice was given and consent was obtained in accordance with the Act. This requires retention of the underlying artefacts, not merely of the current policy. | Z13: Can the entity produce, for a Data Principal selected at random, the notice text as presented at the time, the consent artefact, and the processing history — or can it only produce today's policy? | AA13: Re-perform: select two Data Principals at random and require production of the historical notice version, consent artefact and processing record. | AB13: Versioned archive of notice and consent text with effective dates · Consent artefacts retrievable per Data Principal · Documented evidence retention period aligned to limitation and inquiry risk | AC13: Up to INR 50 crore | AD13: 7 | AE13: Notice versions and consent artefacts are archived and jointly retrievable per Data Principal, and testing confirms the entity can reconstruct precisely what was presented and agreed to, and when.
A14: PUR-01 | B14: PUR | C14: Lawful Purpose, Minimisation & Accuracy | D14: Every processing activity has an identified lawful basis | E14: Critical | F14: =IF(E14="Critical",4,IF(E14="High",3,IF(E14="Medium",2,1))) | G14: 1.3 | H14: Yes | I14: in scope | J14: s.4(1), s.4(2), DPDP Act, 2023 | K14: — | L14: — | M14: 2 | N14: =IF(OR(H14="No",M14="",UPPER(M14)="NA"),0,1) | O14: =IF(H14="No","Out of scope",IF(UPPER(M14)="NA","Not applicable",IF(M14="","Not assessed",IF(M14>=4,"Compliant",IF(M14>=3,"Substantially compliant",IF(M14>=2,"Partially compliant","Non-compliant")))))) | P14: =IF(N14=0,"",F14*(4-M14)) | Q14: =IF(P14="","",IF(P14>=12,"Critical",IF(P14>=8,"High",IF(P14>=4,"Medium",IF(P14>=1,"Low","None"))))) | R14: =IF(AND(N14=1,M14<3),1,0) | S14: =IF(N14=0,"",M14*G14) | T14: =IF(N14=0,"",4*G14) | U14: A lawful basis is documented for the lending and payments journeys. Four activities have no identified basis: the churn model, marketing enrichment from a third-party data broker, call recording in collections, and the employee monitoring noted at GOV-02. Management's position that these fall within 'legitimate business interest' has no counterpart in the Act, which provides a closed list of legitimate uses. | V14: WP-020 | W14: Meera Raghunathan, Head of Legal & Compliance | Y14: Personal data may be processed only for a lawful purpose for which the Data Principal has given consent, or for a certain legitimate use. A lawful purpose is one not expressly forbidden by law. | Z14: Is a specific lawful basis — consent or a named section 7 legitimate use — recorded for every processing activity in the register, with no activity left unmapped or resting on a basis that does not exist under the Act? | AA14: Inspect basis mapping for completeness; re-perform the determination for a sample of five activities, including at least one marketing and one analytics use. | AB14: Lawful basis recorded per activity in the processing register · Reasoning for each legitimate use relied upon, citing the specific limb · Evidence that no activity relies on a ground absent from the Act | AC14: Up to INR 50 crore | AD14: 7 | AE14: Every activity carries a specific, documented and defensible basis citing the exact provision, reviewed on change, with no reliance on grounds the Act does not contain.
A15: PUR-02 | B15: PUR | C15: Lawful Purpose, Minimisation & Accuracy | D15: Data minimisation — collection limited to what is necessary | E15: High | F15: =IF(E15="Critical",4,IF(E15="High",3,IF(E15="Medium",2,1))) | G15: 1.2 | H15: Yes | I15: in scope | J15: s.6(1), s.6(2), DPDP Act, 2023 | K15: — | L15: — | M15: 2 | N15: =IF(OR(H15="No",M15="",UPPER(M15)="NA"),0,1) | O15: =IF(H15="No","Out of scope",IF(UPPER(M15)="NA","Not applicable",IF(M15="","Not assessed",IF(M15>=4,"Compliant",IF(M15>=3,"Substantially compliant",IF(M15>=2,"Partially compliant","Non-compliant")))))) | P15: =IF(N15=0,"",F15*(4-M15)) | Q15: =IF(P15="","",IF(P15>=12,"Critical",IF(P15>=8,"High",IF(P15>=4,"Medium",IF(P15>=1,"Low","None"))))) | R15: =IF(AND(N15=1,M15<3),1,0) | S15: =IF(N15=0,"",M15*G15) | T15: =IF(N15=0,"",4*G15) | U15: The onboarding journey collects marital status, education level and employer address for all applicants irrespective of product. Product management confirmed these fields are used only for a subset of underwriting models and could not evidence necessity for the payments-only journey, which represents roughly 60 per cent of registrations. | V15: WP-021 | W15: Rohit Menon, Head of Product | Y15: Consent signifies agreement to processing of only such personal data as is necessary for the specified purpose, and any part of consent that purports to extend beyond that is invalid to that extent. | Z15: For each collection point, is every field necessary for the stated purpose? Are optional fields distinguished from mandatory ones, and has any field been challenged and removed as a result of review? | AA15: Inspect a sample of collection forms and API payloads field by field against stated purposes; test whether mandatory fields are genuinely necessary. | AB15: Field-level necessity analysis for principal collection points · Distinction between mandatory and optional fields in the interface · Change records showing fields removed following review | AC15: Up to INR 50 crore | AD15: 7 | AE15: Field-level necessity is documented and periodically re-tested, optional fields are clearly distinguished, and there is evidence of fields having actually been removed as unnecessary.
A16: PUR-03 | B16: PUR | C16: Lawful Purpose, Minimisation & Accuracy | D16: Purpose limitation — no undisclosed secondary use | E16: High | F16: =IF(E16="Critical",4,IF(E16="High",3,IF(E16="Medium",2,1))) | G16: 1.2 | H16: Yes | I16: in scope | J16: s.4(1), s.5(1), s.6(1), DPDP Act, 2023 | K16: — | L16: — | M16: 1 | N16: =IF(OR(H16="No",M16="",UPPER(M16)="NA"),0,1) | O16: =IF(H16="No","Out of scope",IF(UPPER(M16)="NA","Not applicable",IF(M16="","Not assessed",IF(M16>=4,"Compliant",IF(M16>=3,"Substantially compliant",IF(M16>=2,"Partially compliant","Non-compliant")))))) | P16: =IF(N16=0,"",F16*(4-M16)) | Q16: =IF(P16="","",IF(P16>=12,"Critical",IF(P16>=8,"High",IF(P16>=4,"Medium",IF(P16>=1,"Low","None"))))) | R16: =IF(AND(N16=1,M16<3),1,0) | S16: =IF(N16=0,"",M16*G16) | T16: =IF(N16=0,"",4*G16) | U16: Transaction data collected for payments processing is used to build propensity segments that are pushed to Meta and Google for acquisition campaigns. The notice presented at registration does not disclose advertising as a purpose. This is undisclosed secondary use of data obtained for a different specified purpose. | V16: WP-022 | W16: Rohit Menon, Head of Product | Y16: Processing must be for the specified purpose for which consent was given. Personal data may not be repurposed for materially different uses without a fresh lawful basis. | Z16: Are there controls preventing personal data collected for one purpose being used for another — particularly transaction data flowing into marketing, or customer data into model training — and is a fresh basis obtained where the purpose is materially new? | AA16: Inspect data flows from primary systems into analytics, marketing and machine-learning environments; test each against the notice given at collection. | AB16: Data flow documentation from collection into secondary environments · Purpose-compatibility assessments for secondary uses · Evidence of fresh notice and consent where purposes were materially extended | AC16: Up to INR 50 crore | AD16: 7 | AE16: Secondary use is gated by documented compatibility assessment, technically constrained where possible, and fresh notice and consent are obtained for materially new purposes with evidence of the gate having been enforced.
A17: PUR-04 | B17: PUR | C17: Lawful Purpose, Minimisation & Accuracy | D17: Accuracy and completeness where data drives decisions or is shared | E17: High | F17: =IF(E17="Critical",4,IF(E17="High",3,IF(E17="Medium",2,1))) | G17: 1.1 | H17: Yes | I17: in scope | J17: s.8(3), DPDP Act, 2023 | K17: — | L17: — | M17: 3 | N17: =IF(OR(H17="No",M17="",UPPER(M17)="NA"),0,1) | O17: =IF(H17="No","Out of scope",IF(UPPER(M17)="NA","Not applicable",IF(M17="","Not assessed",IF(M17>=4,"Compliant",IF(M17>=3,"Substantially compliant",IF(M17>=2,"Partially compliant","Non-compliant")))))) | P17: =IF(N17=0,"",F17*(4-M17)) | Q17: =IF(P17="","",IF(P17>=12,"Critical",IF(P17>=8,"High",IF(P17>=4,"Medium",IF(P17>=1,"Low","None"))))) | R17: =IF(AND(N17=1,M17<3),1,0) | S17: =IF(N17=0,"",M17*G17) | T17: =IF(N17=0,"",4*G17) | U17: Bureau and KYC data feeding underwriting is refreshed at decision time and a correction workflow exists in Kavach CRM. Corrections applied in CRM do not propagate to the Snowflake warehouse, so models and collections lists may run on superseded data for up to 30 days. | V17: WP-023 | W17: Devika Iyer, VP Engineering | Y17: Where personal data is likely to be used to make a decision affecting the Data Principal, or is likely to be disclosed to another Data Fiduciary, the Data Fiduciary must ensure it is complete, accurate and consistent. | Z17: Has the entity identified which processing produces decisions affecting Data Principals or involves disclosure onward, and what controls assure accuracy, completeness and consistency in those specific flows? | AA17: Inspect the inventory of decisioning and disclosure flows; test accuracy controls including validation, reconciliation and correction propagation in a sample flow. | AB17: Inventory of decision-making and onward-disclosure flows · Data quality controls: validation rules, reconciliation, exception handling · Evidence that corrections propagate to downstream recipients and decisions | AC17: Up to INR 50 crore | AD17: 7 | AE17: Decisioning and disclosure flows are inventoried, subject to defined accuracy and consistency controls, and corrections demonstrably propagate downstream with evidence of exception handling.
A18: PUR-05 | B18: PUR | C18: Lawful Purpose, Minimisation & Accuracy | D18: Privacy considered at design stage for new processing | E18: Medium | F18: =IF(E18="Critical",4,IF(E18="High",3,IF(E18="Medium",2,1))) | G18: 1 | H18: Yes | I18: in scope | J18: s.8(4), DPDP Act, 2023 | K18: — | L18: — | M18: 2 | N18: =IF(OR(H18="No",M18="",UPPER(M18)="NA"),0,1) | O18: =IF(H18="No","Out of scope",IF(UPPER(M18)="NA","Not applicable",IF(M18="","Not assessed",IF(M18>=4,"Compliant",IF(M18>=3,"Substantially compliant",IF(M18>=2,"Partially compliant","Non-compliant")))))) | P18: =IF(N18=0,"",F18*(4-M18)) | Q18: =IF(P18="","",IF(P18>=12,"Critical",IF(P18>=8,"High",IF(P18>=4,"Medium",IF(P18>=1,"Low","None"))))) | R18: =IF(AND(N18=1,M18<3),1,0) | S18: =IF(N18=0,"",M18*G18) | T18: =IF(N18=0,"",4*G18) | U18: A privacy review is a documented gate in the product development lifecycle but is discretionary in practice. Of the 11 features released in the period, three carried a completed review. Kavach Junior, the highest-risk launch in the period, went live without one. | V18: WP-024 | W18: Rohit Menon, Head of Product | Y18: Appropriate technical and organisational measures under section 8(4) require that new products, features and vendor engagements are assessed for compliance before personal data is processed, not after. | Z18: Is there a gate in the product and procurement lifecycle requiring privacy assessment before launch, and is there evidence of it having actually blocked or changed a launch? | AA18: Inspect the gate definition and completed assessments; test a sample of recent launches for whether the gate was applied before go-live. | AB18: Defined assessment gate in the product and procurement lifecycle · Completed assessments for recent launches, dated before go-live · Evidence of at least one launch changed or blocked as a result | AC18: — | AE18: The gate is embedded and enforced before go-live, with completed assessments predating launch and evidence of launches having been changed or blocked on privacy grounds.
